<?xml version="1.0"?>
<robot name="scoutbot">

  <link name="base_footprint"/>
  <joint name="base_footprint_to_base_link" type="fixed">
    <parent link="base_footprint"/>
    <child link="base_link"/>
    <origin xyz="0 0 0.05" rpy="0 0 0"/>
  </joint>
  
  <!-- Base box -->
  <link name="base_link">
    <visual>
      <origin xyz="0 0 0" rpy="0 0 0"/>
      <geometry>
        <box size="0.3 0.15 0.1"/>
        <!-- length x width x height -->
      </geometry>
      <material name="red">
        <color rgba="0.9 0.2 0.2 1.0"/>
      </material>
    </visual>
  </link>

  <!-- Lidar -->
  <link name="lidar_link">
    <visual>
      <geometry>
        <cylinder radius="0.03" length="0.05"/>
      </geometry>
      <material name="orange">
        <color rgba="1.0 0.5 0.1 1.0"/>
      </material>
    </visual>
  </link>
  <joint name="lidar_joint" type="fixed">
    <parent link="base_link"/>
    <child link="lidar_link"/>
    <origin xyz="0 0 0.075" rpy="0 0 0"/>
  </joint>

  <!-- Left wheel -->
  <link name="left_wheel">
    <visual>
      <geometry>
        <cylinder radius="0.05" length="0.05"/>
        <origin xyz="0 0 0" rpy="0 0 0"/>
      </geometry>
      <material name="black">
        <color rgba="0.0 0.0 0.0 1.0" />
      </material>
    </visual>
  </link>
  <joint name="left_wheel_joint" type="continuous">
    <parent link="base_link"/>
    <child link="left_wheel"/>
    <!-- <origin xyz="-0.12 0.1035 0" rpy="1.57 0 0"/> -->
    <origin xyz="-0.12 0.1035 -0.035" rpy="1.57 0 0"/>
    <axis xyz="0.0 0.0 1.0"/>
  </joint>


  <!-- Right wheel -->
  <link name="right_wheel">
    <visual>
      <geometry>
        <cylinder radius="0.05" length="0.05"/>
        <origin xyz="0 0 0" rpy="0 0 0"/>
      </geometry>
      <material name="black">
        <color rgba="0.0 0.0 0.0 1.0" />
      </material>
    </visual>
  </link>
  <joint name="right_wheel_joint" type="continuous">
    <parent link="base_link"/>
    <child link="right_wheel"/>
    <!-- <origin xyz="-0.12 -0.1035 0" rpy="1.57 0 0"/> -->
    <origin xyz="-0.12 -0.1035 -0.035" rpy="1.57 0 0"/>
    <axis xyz="0.0 0.0 1.0"/>

  </joint>

  <!-- Front caster wheel -->
  <link name="caster_wheel">
    <visual>
      <geometry>
        <sphere radius="0.02"/>
      </geometry>
      <material name="grey">
        <color rgba="0.6 0.6 0.6 1.0"/>
      </material>
    </visual>
  </link>
  <joint name="caster_joint" type="fixed">
    <parent link="base_link"/>
    <child link="caster_wheel"/>
    <origin xyz="0.1 0 -0.067" rpy="0 0 0"/>
    <!-- front/center, near ground -->
  </joint>

</robot>
